Workbook

Sheet УзлыРесы(1)
B1: По карте (кнопка М) в Игре | C1: Кол-во узлов | D1: Узлы с ресурсами по моим данным: | F1: № | G1: Торговый узел (5): | H1: Область | I1: Производство: | K1: № | L1: Обычный узел (320): | M1: Область | N1: Производство: | P1: № | Q1: Обычный узел (218): | R1: Область | S1: Производство: | U1: № | V1: Обычный узел (218): | W1: Область | X1: Производство:
B2: Города | C2: 11 | D2: =D24+D50+D98+I7+I79+N106+S106+X115 -> 209 | F2: 1 | G2: Ферма Бартелли | H2: Баленос | I2: Картофель. Курица, яйцо. Жареная курица | K2: 1 | L2: Ферма Пинто | M2: Баленос | N2: Картофель. Курица, яйцо. Яблочный джем Пинто | P2: 105 | Q2: Остров Эводин | R2: Кальфеон | S2: --- | U2: 209 | V2: Море Росс 1 | W2: Океан | X2: ---
B3: Поселения | C3: 23 | F3: 2 | G3: Ферма Алехандро | H3: Серендия | I3: Тыква. Мёд. Особый мёд Алехандро | K3: 2 | L3: Каменный зал древних (скрытый) | M3: Баленос | N3: Увядшие листья, треснувший коготь, порошок земли, порошок починки | P3: 106 | Q3: Остров Овэн | R3: Кальфеон | S3: Сушеный дитрем/остронос/килька/язь ! Ставрида/налим/летучая рыба/язь. БАРТЕР | U3: 210 | V3: Море Росс 2 | W3: Океан | X3: ---
B4: Врата | C4: 44 | D4: Проверка кол-ва узлов с ресурсами | F4: 3 | G4: Пастбище каменной пустоши | H4: Медия | I4: Соломенный портфель Аслана | K4: 3 | L4: Пещера бесов | M4: Баленос | N4: Медная руда, пыль огня | P4: 107 | Q4: Остров Дэйтан | R4: Кальфеон | S4: Сушеная ставрида/летучая рыба/налим/судак. БАРТЕР | U4: 211 | V4: Море Росс 3 | W4: Океан | X4: ---
B5: Торговый узел | C5: 5 | D5: ='Баленос-Серендия'!B42+'Баленос-Серендия'!E19+'Кальфеон - СтранаУтра'!B50+'Кальфеон - СтранаУтра'!E17+'Медия-Валенсия'!B27+'Медия-Валенсия'!E38+'Кама-Дриган-Одилита-Горы'!B15+'Кама-Дриган-Одилита-Горы'!B31+'Кама-Дриган-Одилита-Горы'!E12+'Кама-Дриган-Одилита-Горы'!E30 -> 209 | F5: 4 | G5: Лесопилка Дормана | H5: Дриган | I5: Древесина, доска, сок кипариса. Древесина, доска, сок плосковеточника. | K5: 4 | L5: Ферма Лоджи | M5: Баленос | N5: Картофель. Ящик с отборным картофелем | P5: 108 | Q5: Остров Тондэ | R5: Кальфеон | S5: БАРТЕР | U5: 212 | V5: Море Росс 4 | W5: Океан | X5: ---
B6: Опасная облась | C6: 68 | F6: 5 | G6: Грандина | H6: Камасильвия | I6: --- | K6: 5 | L6: Ферма Марино | M6: Баленос | N6: Талисман счастья из прозрачного хрусталя | P6: 109 | Q6: Остров Варатерра | R6: Кальфеон | S6: Сушеный дитрем/остронос/скат/килька ! Остронос/ставрида/летучая рыба/налим | U6: 213 | V6: Море Росс 5 | W6: Океан | X6: ---
B7: Узел | C7: 320 | I7: =F6-COUNTIF(I2:I6,"---") -> 4 | K7: 6 | L7: Руины замка Крон | M7: Баленос | N7: Календула, пучок клендулы | P7: 110 | Q7: Остров Рандис | R7: Кальфеон | S7: Сушеная ставрида/налим/красноперка/осминог ! Осетр/налим/килька/эвус. БАРТЕР | U7: 214 | V7: Море Росс 6 (из 7) | W7: Океан | X7: ---
B8: Итого: | C8: =SUM(C2:C7) -> 471 | K8: 7 | L8: Холм Эхваз | M8: Баленос | N8: Древесина, сок ясеня. Подосиновик, большой подосиновик | P8: 111 | Q8: Остров Серка | R8: Кальфеон | S8: Сушеный остронос/осетр/летучая рыба/карась | U8: 215 | V8: Лагри 1 | W8: Океан | X8: ---
K9: 8 | L9: Лес разбойников | M9: Баленос | N9: Боровик, большой боровик | P9: 112 | Q9: Остров Ваэджа | R9: Кальфеон | S9: Сушеный остронос/ставрида/осьминог/омуль | U9: 216 | V9: Лагри 2 | W9: Океан | X9: ---
F10: № | G10: Опасная область (68): | H10: Область | I10: Производство: | K10: 9 | L10: Лес Баленоса | M10: Баленос | N10: Календула, Пучок календулы. Древесина ясеня, волшебный листок | P10: 113 | Q10: Остров Модрик | R10: Кальфеон | S10: Сушеный дитрем/ставрида/налим/макрель | U10: 217 | V10: Лагри 3 | W10: Океан | X10: ---
F11: 1 | G11: Замок Крон | H11: Баленос | I11: --- | K11: 10 | L11: Ферма Тоскани | M11: Баленос | N11: Кукуруза. Ящик с отборной кукурузой | P11: 114 | Q11: Остров Шионил | R11: Кальфеон | S11: --- | U11: 218 | V11: Лагри 4 | W11: Океан | X11: ---
A12: № | B12: Города (11): | C12: Область | D12: Производство: | F12: 2 | G12: Пещера гоблинов | H12: Баленос | I12: Древесина ясеня, волшебный листок. Медная руда, грубый прозрачный хрусталь | K12: 11 | L12: Прибрежная пещера | M12: Баленос | N12: Железная руда, пыль тьмы. Медная руда, пыль огня | P12: 115 | Q12: Остров Тэямаль | R12: Кальфеон | S12: Сушеная ставрида/килька/макрель/осьминог ! Дитрем/скалярия/ставрида/летучая рыба | U12: 219 | V12: Лагри 5 | W12: Океан | X12: ---
A13: 1 | B13: Велия | C13: Баленос | D13: Золотые слитки, серебро | F13: 3 | G13: Роща отшельников | H13: Баленос | I13: Древесина клёна, ветвь монарха. Медная руда, пыль огня | K13: 12 | L13: Алтарь Агриса | M13: Баленос | N13: --- | P13: 116 | Q13: Остров Рамеда | R13: Кальфеон | S13: --- | U13: 220 | V13: Лагри 6 | W13: Океан | X13: ---
A14: 2 | B14: Хидель | C14: Серендия | D14: Золотые слитки, серебро | F14: 4 | G14: Руины замка | H14: Серендия | I14: Древесина, сок клёна | K14: 13 | L14: Прибрежные скалы | M14: Баленос | N14: Железная руда, пыль тьмы. Подосиновик, большой подосиновик | P14: 117 | Q14: Остров Зинборей | R14: Кальфеон | S14: --- | U14: 221 | V14: Лагри 7 | W14: Океан | X14: ---
A15: 3 | B15: Кальфеон | C15: Кальфеон | D15: Золотые слитки, серебро | F15: 5 | G15: Кровавый монастырь | H15: Серендия | I15: --- | K15: 14 | L15: Врата Флорина | M15: Баленос | N15: --- | P15: 118 | Q15: Остров Нэтном | R15: Кальфеон | S15: --- | U15: 222 | V15: Лагри 8 | W15: Океан | X15: ---
A16: 4 | B16: Алтинова | C16: Медия | D16: Золотые слитки, серебро | F16: 6 | G16: Святилище Серендии | H16: Серендия | I16: Древесина соcны, ветвь монарха | K16: 15 | L16: Мост Ольдстера | M16: Баленос | N16: --- | P16: 119 | Q16: Остров Кайт | R16: Кальфеон | S16: БАРТЕР | U16: 223 | V16: Лагри 9 | W16: Океан | X16: ---
A17: 5 | B17: Валенсия | C17: Валенсия | D17: Золотые слитки, серебро | F17: 7 | G17: Логово Бираги | H17: Серендия | I17: --- | K17: 16 | L17: Ферма Касто | M17: Баленос | N17: Виноград, ящик с отборным виноградом | P17: 120 | Q17: Остров Алрат | R17: Кальфеон | S17: --- | U17: 224 | V17: Лагри 10 | W17: Океан | X17: ---
A18: 6 | B18: Грана | C18: Камасильвия | D18: Древесина/доска пальмы. Кокос | F18: 8 | G18: Форт Брейди | H18: Серендия | I18: --- | K18: 17 | L18: Ферма Вейла | M18: Баленос | N18: Олива, ящик с отборными оливками | P18: 121 | Q18: Остров Эхо | R18: Кальфеон | S18: --- | U18: 225 | V18: Лагри 11 | W18: Океан | X18: ---
A19: 7 | B19: Двенкрун | C19: Дриган | D19: Золотые слитки, серебро | F19: 9 | G19: Южная нейтральная зона | H19: Серендия | I19: --- | K19: 18 | L19: Волчий холм | M19: Баленос | N19: Древесина ясеня | P19: 122 | Q19: Остров Тиссен | R19: Кальфеон | S19: --- | U19: 226 | V19: Лагри 12 | W19: Океан | X19: ---
A20: 8 | B20: Одираксия | C20: Одиллита | D20: --- | F20: 10 | G20: Западный лес Бри | H20: Кальфеон | I20: Древесина, сок ольхи. Опёнок, болшой опёнок | K20: 19 | L20: Устье реки Баленоса | M20: Баленос | N20: --- | P20: 123 | Q20: Остров Амитэ | R20: Кальфеон | S20: --- | U20: 227 | V20: Лагри 13 | W20: Океан | X20: ---
A21: 9 | B21: Око Окилы | C21: Океан | D21: --- | F21: 11 | G21: Пещера Хируто | H21: Кальфеон | I21: --- | K21: 20 | L21: Утес Фудо | M21: Баленос | N21: Медная руда | P21: 124 | Q21: Остров Саллис | R21: Баленос | S21: --- | U21: 228 | V21: Лагри 14 | W21: Океан | X21: ---
A22: 10 | B22: Деревня Эил | C22: Горы вечной зимы | D22: --- | F22: 12 | G22: Хребет Каранды | H22: Кальфеон | I22: Черноголовка, пучок черноголовки | K22: 21 | L22: Предгорье Фудо | M22: Баленос | N22: --- | P22: 125 | Q22: Остров Розы | R22: Баленос | S22: --- | U22: 229 | V22: Лагри 15 | W22: Океан | X22: ---
A23: 11 | B23: Мутыль | C23: Страна Утра | D23: --- | F23: 13 | G23: Хребет дьявола | H23: Кальфеон | I23: Древесина ольхи, красная почка | K23: 22 | L23: Побережъе Оливии | M23: Баленос | N23: --- | P23: 126 | Q23: Коралловый остров | R23: Баленос | S23: --- | U23: 230 | V23: Лагри 16 (из 29) | W23: Океан | X23: ---
D24: =A23-COUNTIF(D13:D23,"---") -> 7 | F24: 14 | G24: Пещера Кафрас | H24: Кальфеон | I24: --- | K24: 23 | L24: Плато Эферии | M24: Баленос | N24: --- | P24: 127 | Q24: Остров Веры (скрытый) | R24: Баленос | S24: Чертеж фигура Чиро, звездный порошок, железная руда | U24: 231 | V24: Воды Эур 1 | W24: Океан | X24: ---
F25: 15 | G25: Перевал Эви | H25: Кальфеон | I25: Древесина кедра, ветвь монарха | K25: 24 | L25: Лес Сипух | M25: Баленос | N25: --- | P25: 128 | Q25: Остров Хошита (скрытый) | R25: Баленос | S25: Чертеж черный парус Чиро, звездный порошок, железная руда | U25: 232 | V25: Воды Эур 2 | W25: Океан | X25: ---
A26: № | B26: Поселения (23) | C26: Область | D26: Производство: | F26: 16 | G26: Лагерь Сонил | H26: Кальфеон | I26: --- | K26: 25 | L26: Ферма Коста | M26: Серендия | N26: Пшеница. Тыква. Лён, льняная нить. Ящик с отборной тыквой | P26: 129 | Q26: Каменная пустошь | R26: Медия | S26: Древесина / сок акации. Сучок кровавого дерева | U26: 233 | V26: Воды Эур 3 (из 7) | W26: Океан | X26: ---
A27: 1 | B27: Западный лагерь стражников | C27: Баленос | D27: --- | F27: 17 | G27: Первый лагерь гигантов | H27: Кальфеон | I27: Свинцовая руда, пыль разрушения | K27: 26 | L27: Плантация Моретти | M27: Серендия | N27: Пшеница. Лён, льняная нить. Ящик с отборной пшеницей | P27: 130 | Q27: Северное плато Медии | R27: Медия | S27: Древесина / сок пихты, кора старого дерева. Древесина / сок клёна, кора старого дерева. | U27: 234 | V27: Пустое море 1 | W27: Океан | X27: ---
A28: 2 | B28: Город Оливия | C28: Баленос | D28: Ящик с древесиной из Баленоса | F28: 18 | G28: Граница Сонил | H28: Кальфеон | I28: --- | K28: 27 | L28: Шахта Хиделя | M28: Серендия | N28: Железная руда, пыль тьмы. Медная руда, пыль огня | P28: 131 | Q28: Земля Эха | R28: Медия | S28: --- | U28: 235 | V28: Пустое море 2 | W28: Океан | X28: ---
A29: 3 | B29: Город Глиши | C29: Серендия | D29: Ящик с отборным Подберёзовиком + золотые слитки, серебро | F29: 19 | G29: Лаборатория Марни | H29: Кальфеон | I29: --- | K29: 28 | L29: Ранчо Линчей | M29: Серендия | N29: Шерсть, шерстяная нить | P29: 132 | Q29: Храм Камасильва | R29: Медия | S29: Лен, льняная нить. Опёнок, большой опенок. | U29: 236 | V29: Пустое море 3 | W29: Океан | X29: ---
A30: 4 | B30: Кеплан | C30: Кальфеон | D30: Золотые слитки, серебро | F30: 20 | G30: Заброшенная шахта | H30: Кальфеон | I30: --- | K30: 29 | L30: Северная равнина Серендии | M30: Серендия | N30: Азалия. Древесина клёна, красная почка | P30: 133 | Q30: Плато Асула | R30: Медия | S30: --- | U30: 237 | V30: Пустое море 4 (из 8) | W30: Океан | X30: ---
A31: 5 | B31: Деревня Флорин | C31: Кальфеон | D31: Ящик трав Флорина + золотые слитки, серебро | F31: 21 | G31: Пещера глутонов | H31: Кальфеон | I31: Уголь, пыль разрушения. Вешенка, большая вешенка | K31: 30 | L31: Болота Глиши | M31: Серендия | N31: Подберёзовик, большой Подберёзовик. Свинцовая руда, пыль веков | P31: 134 | Q31: Вход в Алтинову | R31: Медия | S31: --- | U31: 238 | V31: Лагри залив Велла | W31: Океан | X31: ---
A32: 6 | B32: Портовый город Эферия | C32: Кальфеон | D32: Ящик морепродуктов (сиган) | F32: 22 | G32: Дом Оджи | H32: Кальфеон | I32: --- | K32: 31 | L32: Южное болото | M32: Серендия | N32: Железная руда, грубый черный хрусталь. Подберёзовик, большой Подберёзовик. Тайное послание | P32: 135 | Q32: Долина Алум | R32: Медия | S32: --- | U32: 239 | V32: Пруд Антаци | W32: Камасильвия | X32: Сияние Антаци
A33: 7 | B33: Деревня Трент | C33: Кальфеон | D33: Ящик с древесиной из Кальфеона | F33: 23 | G33: Лес Энтов | H33: Кальфеон | I33: Древесина кипариса, сучок кровавого дерева | K33: 32 | L33: Руины Глиши | M33: Серендия | N33: Чёрная земля, острый обломок шлема, затупленный осколок, порошок изначальности /охотников | P33: 136 | Q33: Каменный клюв | R33: Медия | S33: --- | U33: 240 | V33: Лес Каду | W33: Камасильвия | X33: ---
A34: 8 | B34: Медвежья деревня | C34: Кальфеон | D34: Ящик с древесиной из Кальфеона | F34: 24 | G34: Лагерь Ратамов | H34: Кальфеон | I34: Оловянная руда, грубый зеленый хрусталь | K34: 33 | L34: Северные болота | M34: Серендия | N34: Головач, большой головач. Ящик с отборным головачом | P34: 137 | Q34: Лавовая пещера (скрытый) | R34: Медия | S34: Цинковая руда, пыль веков, платиновая руда. Уголь, пыль разрушения, грубый рубин | U34: 241 | V34: Тенистый лес | W34: Камасильвия | X34: Мшистая древесина/доска. Сок мшистого дерева
A35: 9 | B35: Северное поле пшеницы | C35: Кальфеон | D35: Перец. Пшеница. Ячмень. Ящик с отборным подсолнухом + золотые слитки, серебро | F35: 25 | G35: Лагерь водяных | H35: Кальфеон | I35: --- | K35: 34 | L35: Руины фермы Линчей (скрытый) | M35: Серендия | N35: Азалия. Сломаный рог, колесо телеги, тканьжилища бесов. Порошок варваров / охотников | P35: 138 | Q35: Гробница правителей | R35: Медия | S35: --- | U35: 242 | V35: Одинокий лес | W35: Камасильвия | X35: Зеленая руда, пыль веков
A36: 10 | B36: Остров Лема | C36: Баленос | D36: --- | F36: 26 | G36: Западный лес Кальфеона | H36: Кальфеон | I36: --- | K36: 35 | L36: Лагерь сайджеков | M36: Серендия | N36: --- | P36: 139 | Q36: Место раскопок (Скрытый) | R36: Медия | S36: Потускневший фрагмент голема, осколок украшения клана Тугу, Порошок земли / хаоса | U36: 243 | V36: Горная деревня | W36: Камасильвия | X36: Клубника, хорошая клубника
A37: 11 | B37: Остров Илия | C37: Баленос | D37: Амулет Илии | F37: 27 | G37: Тёмный лес | H37: Кальфеон | I37: Древесина, сок кедра | K37: 36 | L37: Сторожевая башня | M37: Серендия | N37: --- | P37: 140 | Q37: Ферма Эхто | R37: Медия | S37: Хлопок, хлопокове полотно. Алоэ. Мешочек с семенами Моны. | U37: 244 | V37: Горы Вельтара | W37: Камасильвия | X37: ---
A38: 12 | B38: Деревня Тариффа | C38: Медия | D38: Кувшин заклинателя Тариф | F38: 28 | G38: Ведьмин дол | H38: Кальфеон | I38: --- | K38: 37 | L38: Земли прокаженых | M38: Кальфеон | N38: --- | P38: 141 | Q38: Ферма Сури | R38: Медия | S38: Батат, хороший батат, отборный батат. Ящик с отборным бататом | U38: 245 | V38: Западный хребет Вельтара | W38: Камасильвия | X38: ---
... A49: 23 | B49: Рисовая деревня | C49: Страна Утра | D49: Рис / Петсай / Редька / Красная азалия / Розовая азалия | F49: 39 | G49: Храм Эллик | H49: Медия | I49: Древесина, сок пихты. Сучок кровавого дерева. Волнушка, большая волнушка | K49: 48 | L49: Угодья Бейн | M49: Кальфеон | N49: Ящик с отборной кукурузой | P49: 152 | Q49: Змеиная пустошь | R49: Валенсия | S49: Древесина/доска/сок бузины. Фисташки | U49: 256 | V49: Поля Двенкруна | W49: Дриган | X49: Ячмень. Кукуруза
D50: =A49-COUNTIF(D27:D49,"---") -> 16 | F50: 40 | G50: Лагерь клана Тугу | H50: Медия | I50: --- | K50: 49 | L50: Ферама Оберен | M50: Кальфеон | N50: --- | P50: 153 | Q50: Ущелье скорби | R50: Валенсия | S50: Древесина/доска/сок бузины. | U50: 257 | V50: Каньон Карков | W50: Дриган | X50: Зеленая руда. Мельхиор. Цинковая руда.
...

Sheet + Фильтр узлы + ресурсы
A1: Автор гайда (и этой таблички) по добыче ресурсов на узлах и баракам для рабов в БДО - Стаффи
A3: Область | B3: Узлы Добычи (647 штук) | C3: Добываемый ресурс
A4: ='УзлыРесы(1)'!C13 -> Баленос | B4: ='УзлыРесы(1)'!B13 -> Велия | C4: Золотые слитки
A5: =A4 -> Баленос | B5: =B4 -> Велия | C5: Серебро
A6: =A5 -> Баленос | B6: ='УзлыРесы(1)'!B28 -> Город Оливия | C6: ='УзлыРесы(1)'!D28 -> Ящик с древесиной из Баленоса
A7: =A6 -> Баленос | B7: ='УзлыРесы(1)'!B37 -> Остров Илия | C7: ='УзлыРесы(1)'!D37 -> Амулет Илии
A8: =A7 -> Баленос | B8: ='УзлыРесы(1)'!G2 -> Ферма Бартелли | C8: Картофель
A9: =A8 -> Баленос | B9: =B8 -> Ферма Бартелли | C9: Курица
A10: =A9 -> Баленос | B10: =B9 -> Ферма Бартелли | C10: Яйцо
A11: =A10 -> Баленос | B11: =B10 -> Ферма Бартелли | C11: Жареная курица
A12: =A11 -> Баленос | B12: ='УзлыРесы(1)'!L2 -> Ферма Пинто | C12: Картофель
A13: =A12 -> Баленос | B13: =B12 -> Ферма Пинто | C13: Курица
A14: =A13 -> Баленос | B14: =B13 -> Ферма Пинто | C14: Яйцо
A15: =A14 -> Баленос | B15: =B14 -> Ферма Пинто | C15: Яблочный джем Пинто
A16: =A15 -> Баленос | B16: ='УзлыРесы(1)'!L5 -> Ферма Лоджи | C16: Картофель
A17: =A16 -> Баленос | B17: =B16 -> Ферма Лоджи | C17: Ящик с отборным картофелем
A18: =A17 -> Баленос | B18: ='УзлыРесы(1)'!L6 -> Ферма Марино | C18: ='УзлыРесы(1)'!N6 -> Талисман счастья из прозрачного хрусталя
A19: =A18 -> Баленос | B19: ='УзлыРесы(1)'!L10 -> Лес Баленоса | C19: Календула
A20: =A19 -> Баленос | B20: =B19 -> Лес Баленоса | C20: Пучок календулы
A21: =A20 -> Баленос | B21: =B20 -> Лес Баленоса | C21: Древесина ясеня
A22: =A21 -> Баленос | B22: =B21 -> Лес Баленоса | C22: Волшебный листок
A23: =A22 -> Баленос | B23: ='УзлыРесы(1)'!L11 -> Ферма Тоскани | C23: Кукуруза
A24: =A23 -> Баленос | B24: =B23 -> Ферма Тоскани | C24: Ящик с отборной кукурузой
A25: =A24 -> Баленос | B25: ='УзлыРесы(1)'!L79 -> Остров Расиды (скрытый) | C25: Чертеж парус Чиро
A26: =A25 -> Баленос | B26: =B25 -> Остров Расиды (скрытый) | C26: Звездный порошок
A27: =A26 -> Баленос | B27: =B26 -> Остров Расиды (скрытый) | C27: Железная руда
A28: =A27 -> Баленос | B28: ='УзлыРесы(1)'!L89 -> Остров Рувиано | C28: Сушеная корифена
A29: =A28 -> Баленос | B29: =B28 -> Остров Рувиано | C29: Сушеный дитрем
A30: =A29 -> Баленос | B30: =B29 -> Остров Рувиано | C30: Сушеный плотос
A31: =A30 -> Баленос | B31: =B30 -> Остров Рувиано | C31: Сушеный бонит
A32: =A31 -> Баленос | B32: ='УзлыРесы(1)'!L101 -> Остров Руруба | C32: Сушеный плотос
A33: =A32 -> Баленос | B33: =B32 -> Остров Руруба | C33: Сушеная рыба клоун
A34: =A33 -> Баленос | B34: =B33 -> Остров Руруба | C34: Сушеный тамарин
A35: =A34 -> Баленос | B35: =B34 -> Остров Руруба | C35: Сушеный тунец
A36: =A35 -> Баленос | B36: ='УзлыРесы(1)'!G12 -> Пещера гоблинов | C36: Древесина ясеня
A37: =A36 -> Баленос | B37: =B36 -> Пещера гоблинов | C37: Волшебный листок
A38: =A37 -> Баленос | B38: =B37 -> Пещера гоблинов | C38: Медная руда
A39: =A38 -> Баленос | B39: =B38 -> Пещера гоблинов | C39: Грубый прозрачный хрусталь
A40: =A39 -> Баленос | B40: ='УзлыРесы(1)'!G13 -> Роща отшельников | C40: Древесина клена
A41: =A40 -> Баленос | B41: =B40 -> Роща отшельников | C41: Ветвь монарха
...

Sheet Баленос-Серендия
A1: Автор гайда (и этой таблички) по добыче ресурсов на узлах и баракам для рабов в БДО - Стаффи
A3: Узлы Баленоса (38 шт.) | B3: Добываемый ресурс | D3: Узлы Серендии (15 шт.) | E3: Добываемый ресурс
A4: ='УзлыРесы(1)'!B13 -> Велия | B4: ='УзлыРесы(1)'!D13 -> Золотые слитки, серебро | D4: ='УзлыРесы(1)'!B14 -> Хидель | E4: ='УзлыРесы(1)'!D14 -> Золотые слитки, серебро
A5: ='УзлыРесы(1)'!B28 -> Город Оливия | B5: ='УзлыРесы(1)'!D28 -> Ящик с древесиной из Баленоса | D5: ='УзлыРесы(1)'!B29 -> Город Глиши | E5: ='УзлыРесы(1)'!D29 -> Ящик с отборным Подберёзовиком + золотые слитки, серебро
A6: ='УзлыРесы(1)'!B37 -> Остров Илия | B6: ='УзлыРесы(1)'!D37 -> Амулет Илии | D6: ='УзлыРесы(1)'!G3 -> Ферма Алехандро | E6: ='УзлыРесы(1)'!I3 -> Тыква. Мёд. Особый мёд Алехандро
A7: ='УзлыРесы(1)'!G2 -> Ферма Бартелли | B7: ='УзлыРесы(1)'!I2 -> Картофель. Курица, яйцо. Жареная курица | D7: ='УзлыРесы(1)'!L26 -> Ферма Коста | E7: ='УзлыРесы(1)'!N26 -> Пшеница. Тыква. Лён, льняная нить. Ящик с отборной тыквой
A8: ='УзлыРесы(1)'!L2 -> Ферма Пинто | B8: ='УзлыРесы(1)'!N2 -> Картофель. Курица, яйцо. Яблочный джем Пинто | D8: ='УзлыРесы(1)'!L27 -> Плантация Моретти | E8: ='УзлыРесы(1)'!N27 -> Пшеница. Лён, льняная нить. Ящик с отборной пшеницей
A9: ='УзлыРесы(1)'!L5 -> Ферма Лоджи | B9: ='УзлыРесы(1)'!N5 -> Картофель. Ящик с отборным картофелем | D9: ='УзлыРесы(1)'!L29 -> Ранчо Линчей | E9: ='УзлыРесы(1)'!N29 -> Шерсть, шерстяная нить
A10: ='УзлыРесы(1)'!L6 -> Ферма Марино | B10: ='УзлыРесы(1)'!N6 -> Талисман счастья из прозрачного хрусталя | D10: ='УзлыРесы(1)'!L34 -> Северные болота | E10: ='УзлыРесы(1)'!N34 -> Головач, большой головач. Ящик с отборным головачом
A11: ='УзлыРесы(1)'!L10 -> Лес Баленоса | B11: ='УзлыРесы(1)'!N10 -> Календула, Пучок календулы. Древесина ясеня, волшебный листок | D11: ='УзлыРесы(1)'!G14 -> Руины замка | E11: ='УзлыРесы(1)'!I14 -> Древесина, сок клёна
A12: ='УзлыРесы(1)'!L11 -> Ферма Тоскани | B12: ='УзлыРесы(1)'!N11 -> Кукуруза. Ящик с отборной кукурузой | D12: ='УзлыРесы(1)'!G16 -> Святилище Серендии | E12: ='УзлыРесы(1)'!I16 -> Древесина соcны, ветвь монарха
A13: ='УзлыРесы(1)'!L79 -> Остров Расиды (скрытый) | B13: ='УзлыРесы(1)'!N79 -> Чертеж парус Чиро, звездный порошок, железная руда | D13: ='УзлыРесы(1)'!L28 -> Шахта Хиделя | E13: ='УзлыРесы(1)'!N28 -> Железная руда, пыль тьмы. Медная руда, пыль огня
A14: ='УзлыРесы(1)'!L89 -> Остров Рувиано | B14: ='УзлыРесы(1)'!N89 -> Сушеная корифена/дитрем/плотос/бонит | D14: ='УзлыРесы(1)'!L30 -> Северная равнина Серендии | E14: ='УзлыРесы(1)'!N30 -> Азалия. Древесина клёна, красная почка
A15: ='УзлыРесы(1)'!L101 -> Остров Руруба | B15: ='УзлыРесы(1)'!N101 -> Сушеный плотос/рыба-клоун/тамарин/тунец | D15: ='УзлыРесы(1)'!L31 -> Болота Глиши | E15: ='УзлыРесы(1)'!N31 -> Подберёзовик, большой Подберёзовик. Свинцовая руда, пыль веков
A16: ='УзлыРесы(1)'!G12 -> Пещера гоблинов | B16: ='УзлыРесы(1)'!I12 -> Древесина ясеня, волшебный листок. Медная руда, грубый прозрачный хрусталь | D16: ='УзлыРесы(1)'!L32 -> Южное болото | E16: ='УзлыРесы(1)'!N32 -> Железная руда, грубый черный хрусталь. Подберёзовик, большой Подберёзовик. Тайное послание
A17: ='УзлыРесы(1)'!G13 -> Роща отшельников | B17: ='УзлыРесы(1)'!I13 -> Древесина клёна, ветвь монарха. Медная руда, пыль огня | D17: ='УзлыРесы(1)'!L33 -> Руины Глиши | E17: ='УзлыРесы(1)'!N33 -> Чёрная земля, острый обломок шлема, затупленный осколок, порошок изначальности /охотников
A18: ='УзлыРесы(1)'!L3 -> Каменный зал древних (скрытый) | B18: ='УзлыРесы(1)'!N3 -> Увядшие листья, треснувший коготь, порошок земли, порошок починки | D18: ='УзлыРесы(1)'!L35 -> Руины фермы Линчей (скрытый) | E18: ='УзлыРесы(1)'!N35 -> Азалия. Сломаный рог, колесо телеги, тканьжилища бесов. Порошок варваров / охотников
A19: ='УзлыРесы(1)'!L4 -> Пещера бесов | B19: ='УзлыРесы(1)'!N4 -> Медная руда, пыль огня | E19: 15
A20: ='УзлыРесы(1)'!L7 -> Руины замка Крон | B20: ='УзлыРесы(1)'!N7 -> Календула, пучок клендулы
A21: ='УзлыРесы(1)'!L8 -> Холм Эхваз | B21: ='УзлыРесы(1)'!N8 -> Древесина, сок ясеня. Подосиновик, большой подосиновик
A22: ='УзлыРесы(1)'!L9 -> Лес разбойников | B22: ='УзлыРесы(1)'!N9 -> Боровик, большой боровик
A23: ='УзлыРесы(1)'!L12 -> Прибрежная пещера | B23: ='УзлыРесы(1)'!N12 -> Железная руда, пыль тьмы. Медная руда, пыль огня
A24: ='УзлыРесы(1)'!L14 -> Прибрежные скалы | B24: ='УзлыРесы(1)'!N14 -> Железная руда, пыль тьмы. Подосиновик, большой подосиновик
A25: ='УзлыРесы(1)'!L17 -> Ферма Касто | B25: ='УзлыРесы(1)'!N17 -> Виноград, ящик с отборным виноградом
A26: ='УзлыРесы(1)'!L18 -> Ферма Вейла | B26: ='УзлыРесы(1)'!N18 -> Олива, ящик с отборными оливками
A27: ='УзлыРесы(1)'!L19 -> Волчий холм | B27: ='УзлыРесы(1)'!N19 -> Древесина ясеня
A28: ='УзлыРесы(1)'!L21 -> Утес Фудо | B28: ='УзлыРесы(1)'!N21 -> Медная руда
A29: ='УзлыРесы(1)'!L76 -> Остров Фузара | B29: ='УзлыРесы(1)'!N76 -> Сушеный сазан/бонит/рыба-клоун/марлин ! Плотос/корифена/бонит/нитипер
A30: ='УзлыРесы(1)'!L78 -> Остров Альхана (скрытый) | B30: ='УзлыРесы(1)'!N78 -> Чертеж пушка Чиро, звездный порошок, железная руда
A31: ='УзлыРесы(1)'!L81 -> Остров Войта | B31: ='УзлыРесы(1)'!N81 -> Сушеный тернем/дитреция/красноперка/омуль
A32: ='УзлыРесы(1)'!L87 -> Остров Орфс | B32: ='УзлыРесы(1)'!N87 -> Сушеная ставрида/плотос/корифена/барбус ! Сазан/дитрем/рыба-клоун/барбус
A33: ='УзлыРесы(1)'!L91 -> Остров Маривэйно | B33: ='УзлыРесы(1)'!N91 -> Сушеный плотос/тернеция/рыба-клоун/сиган ! Плотос/сазан/бонит/сиган
A34: ='УзлыРесы(1)'!L92 -> Остров Фаратама | B34: ='УзлыРесы(1)'!N92 -> Сушеный плотос/дитрем/язь/омуль
A35: ='УзлыРесы(1)'!L96 -> Остров Инвонен | B35: ='УзлыРесы(1)'!N96 -> Сушеный плотос/ставрила/корифена/морской черт ! Ставрида/корифена/плотос/бонит
A36: ='УзлыРесы(1)'!L97 -> Остров Анджу | B36: ='УзлыРесы(1)'!N97 -> Сушеный плотос/сазан/бонит/тернеция ! Корифена/плотос/тернеция/рыба-клоун
A37: ='УзлыРесы(1)'!L99 -> Остров Эфдэ Рун | B37: ='УзлыРесы(1)'!N99 -> Сушеная корифена/плотос/сазан/бонит
A38: ='УзлыРесы(1)'!L102 -> Остров Старэн | B38: ='УзлыРесы(1)'!N102 -> Сушенный плотос/осетр/тамарин/тунец ! Корифена/сазан/окунь/коилия
A39: ='УзлыРесы(1)'!L103 -> Остров Рисч | B39: ='УзлыРесы(1)'!N103 -> Сушенный плотос/тернеция/тамарин/тунец ! Корифена/сазан/бонит/коилия
A40: ='УзлыРесы(1)'!Q24 -> Остров Веры (скрытый) | B40: ='УзлыРесы(1)'!S24 -> Чертеж фигура Чиро, звездный порошок, железная руда
A41: ='УзлыРесы(1)'!Q25 -> Остров Хошита (скрытый) | B41: ='УзлыРесы(1)'!S25 -> Чертеж черный парус Чиро, звездный порошок, железная руда
...

Sheet Кальфеон - СтранаУтра
A1: Автор гайда (и этой таблички) по добыче ресурсов на узлах и баракам для рабов в БДО - Стаффи
A3: Узлы Кальфеона (46 шт.) | B3: Добываемый ресурс | D3: Узлы Страны утра (46 шт.) | E3: Добываемый ресурс
A4: ='УзлыРесы(1)'!B15 -> Кальфеон | B4: ='УзлыРесы(1)'!D15 -> Золотые слитки, серебро | D4: ='УзлыРесы(1)'!B49 -> Рисовая деревня | E4: ='УзлыРесы(1)'!D49 -> Рис / Петсай / Редька / Красная азалия / Розовая азалия
A5: ='УзлыРесы(1)'!B30 -> Кеплан | B5: ='УзлыРесы(1)'!D30 -> Золотые слитки, серебро | D5: ='УзлыРесы(1)'!V99 -> Деравня мечников | E5: ='УзлыРесы(1)'!X99 -> Малина, хурма
A6: ='УзлыРесы(1)'!B31 -> Деревня Флорин | B6: ='УзлыРесы(1)'!D31 -> Ящик трав Флорина + золотые слитки, серебро | D6: ='УзлыРесы(1)'!V101 -> Сосновый лес | E6: ='УзлыРесы(1)'!X101 -> Орляк
A7: ='УзлыРесы(1)'!B32 -> Портовый город Эферия | B7: ='УзлыРесы(1)'!D32 -> Ящик морепродуктов (сиган) | D7: ='УзлыРесы(1)'!V103 -> Лес Токкэби | E7: ='УзлыРесы(1)'!X103 -> Порошок земли / починки, Грубый прозрачный хрусталь, Таинственный порошок, Искра сияющей добродетели, Кристалл леса / гармонии
A8: ='УзлыРесы(1)'!B33 -> Деревня Трент | B8: ='УзлыРесы(1)'!D33 -> Ящик с древесиной из Кальфеона | D8: ='УзлыРесы(1)'!V104 -> Пещера золотой свиньи | E8: ='УзлыРесы(1)'!X104 -> Кристалл тени / ожесточения, Порошок варваров, Таинственный порошок,
A9: ='УзлыРесы(1)'!B34 -> Медвежья деревня | B9: ='УзлыРесы(1)'!D34 -> Ящик с древесиной из Кальфеона | D9: ='УзлыРесы(1)'!V105 -> Плато Коун | E9: ='УзлыРесы(1)'!X105 -> Тростник
A10: ='УзлыРесы(1)'!B35 -> Северное поле пшеницы | B10: ='УзлыРесы(1)'!D35 -> Перец. Пшеница. Ячмень. Ящик с отборным подсолнухом + золотые слитки, серебро | D10: ='УзлыРесы(1)'!V107 -> Весенний край | E10: ='УзлыРесы(1)'!X107 -> Древеснина / сок сосны, Орляк
A11: ='УзлыРесы(1)'!L41 -> Ферма Диас | B11: ='УзлыРесы(1)'!N41 -> Ящик с отборными помидорами | D11: ='УзлыРесы(1)'!V108 -> Застава красных разбойников | E11: ='УзлыРесы(1)'!X108 -> Древеснина / сок сосны, Орляк
A12: ='УзлыРесы(1)'!L44 -> Ферма Бернито (скрытый) | B12: ='УзлыРесы(1)'!N44 -> Заражёный клык, осколок скульптыры / артефакта, порошок битвы / леса | D12: ='УзлыРесы(1)'!V109 -> Лисий перевал | E12: ='УзлыРесы(1)'!X109 -> Малина, фиалка
A13: ='УзлыРесы(1)'!L47 -> Ранчо Фаарс | B13: ='УзлыРесы(1)'!N47 -> Кукурузный хлеб | D13: ='УзлыРесы(1)'!V110 -> Лес Пари | E13: ='УзлыРесы(1)'!X110 -> Тигровый цветок, древесина кедра, волшебный листок
A14: ='УзлыРесы(1)'!L49 -> Угодья Бейн | B14: ='УзлыРесы(1)'!N49 -> Ящик с отборной кукурузой | D14: ='УзлыРесы(1)'!V111 -> Тигриное нагорье | E14: ='УзлыРесы(1)'!X111 -> Древесина/сок клена, кора старого дерева. Тигровый цветок.Кристалл уничтожения, порошок земли, таинственный порошок
A15: ='УзлыРесы(1)'!L55 -> Ферма Джанни | B15: ='УзлыРесы(1)'!N55 -> Ящик с отборной черноголовкой | D15: ='УзлыРесы(1)'!V112 -> Остров Хеммо | E15: ='УзлыРесы(1)'!X112 -> Порошок памяти, таинственный порошок
A16: ='УзлыРесы(1)'!L65 -> Ферма Габино | B16: ='УзлыРесы(1)'!N65 -> Ящик с отборным подсолнухом | D16: ='УзлыРесы(1)'!V114 -> Пристань Таллэ (Шахта пристани Таллэ) | E16: ='УзлыРесы(1)'!X114 -> Чертеж пушка/парус/фигура/крепкая обшивка Пёкке, Звездный порошое, Таинственный порошок
A17: ='УзлыРесы(1)'!L66 -> Лес Манш (скрытый) | B17: ='УзлыРесы(1)'!N66 -> Древесина, сок кипариса, Старый коготь, шкура медведя, проклятый осколок, порошок пепла / вреда | E17: 13
A18: ='УзлыРесы(1)'!L70 -> Лесной сторожевой пост | B18: ='УзлыРесы(1)'!N70 -> Черноголоска, пучок черноголовки. Стрела скаутов
A19: ='УзлыРесы(1)'!L71 -> Хижина Фонеля | B19: ='УзлыРесы(1)'!N71 -> Древесина, сок кипариса.
A20: ='УзлыРесы(1)'!L105 -> Остров Альбрессо | B20: ='УзлыРесы(1)'!N105 -> Сушеный остронос/скат/килька/осминог
A21: ='УзлыРесы(1)'!Q4 -> Остров Дэйтан | B21: ='УзлыРесы(1)'!S4 -> Сушеная ставрида/летучая рыба/налим/судак. БАРТЕР
A22: ='УзлыРесы(1)'!Q7 -> Остров Рандис | B22: ='УзлыРесы(1)'!S7 -> Сушеная ставрида/налим/красноперка/осминог ! Осетр/налим/килька/эвус. БАРТЕР
A23: ='УзлыРесы(1)'!B64 -> Замок рыцарей Дельпе | B23: ='УзлыРесы(1)'!D64 -> Талисман любви из красного хрусталя
A24: ='УзлыРесы(1)'!G20 -> Западный лес Бри | B24: ='УзлыРесы(1)'!I20 -> Древесина, сок ольхи. Опёнок, болшой опёнок
A25: ='УзлыРесы(1)'!G22 -> Хребет Каранды | B25: ='УзлыРесы(1)'!I22 -> Черноголовка, пучок черноголовки
A26: ='УзлыРесы(1)'!G23 -> Хребет дьявола | B26: ='УзлыРесы(1)'!I23 -> Древесина ольхи, красная почка
A27: ='УзлыРесы(1)'!G25 -> Перевал Эви | B27: ='УзлыРесы(1)'!I25 -> Древесина кедра, ветвь монарха
A28: ='УзлыРесы(1)'!G27 -> Первый лагерь гигантов | B28: ='УзлыРесы(1)'!I27 -> Свинцовая руда, пыль разрушения
A29: ='УзлыРесы(1)'!G31 -> Пещера глутонов | B29: ='УзлыРесы(1)'!I31 -> Уголь, пыль разрушения. Вешенка, большая вешенка
A30: ='УзлыРесы(1)'!G33 -> Лес Энтов | B30: ='УзлыРесы(1)'!I33 -> Древесина кипариса, сучок кровавого дерева
A31: ='УзлыРесы(1)'!G34 -> Лагерь Ратамов | B31: ='УзлыРесы(1)'!I34 -> Оловянная руда, грубый зеленый хрусталь
A32: ='УзлыРесы(1)'!G37 -> Тёмный лес | B32: ='УзлыРесы(1)'!I37 -> Древесина, сок кедра
A33: ='УзлыРесы(1)'!G78 -> Звездная гробница | B33: ='УзлыРесы(1)'!I78 -> Сгусток чистых чар. Порошок вреда/смерти. Медная руда, кусок меди. Раскрошившийся осколок звезды
A34: ='УзлыРесы(1)'!L39 -> Холм Квинт | B34: ='УзлыРесы(1)'!N39 -> Древесина ольхи, красная почка. Свинцовая руда, пыль веков
A35: ='УзлыРесы(1)'!L42 -> Долина Эферии | B35: ='УзлыРесы(1)'!N42 -> Волнушка, большая волнушка
A36: ='УзлыРесы(1)'!L48 -> Рубеж мертвых | B36: ='УзлыРесы(1)'!N48 -> Железная руда, пыль тьмы
A37: ='УзлыРесы(1)'!L57 -> Шахта Кеплана | B37: ='УзлыРесы(1)'!N57 -> Уголь, пыль разрушения
A38: ='УзлыРесы(1)'!L61 -> Истоки медвежьей реки (скрытый) | B38: ='УзлыРесы(1)'!N61 -> Оловянная руда, пыль притяжения
A39: ='УзлыРесы(1)'!L64 -> Древо Руя (скрытый) | B39: ='УзлыРесы(1)'!N64 -> Вешенка, большая вешенка. Костяное ожерелье, старый коготь, Угаснувший порошок, прошок пепла / леса
A40: ='УзлыРесы(1)'!L67 -> Пещера Мари | B40: ='УзлыРесы(1)'!N67 -> Древесина / сок сосны. Груздь, большой груздь
A41: ='УзлыРесы(1)'!L69 -> Хижина дровосека | B41: ='УзлыРесы(1)'!N69 -> Древесина кедра, волшебный листок
...

Sheet Медия-Валенсия
A1: Автор гайда (и этой таблички) по добыче ресурсов на узлах и баракам для рабов в БДО - Стаффи
A3: Узлы Медии (23 шт.) | B3: Добываемый ресурс | D3: Узлы Валенсии (34.шт.) | E3: Добываемый ресурс
A4: ='УзлыРесы(1)'!B16 -> Алтинова | B4: ='УзлыРесы(1)'!D16 -> Золотые слитки, серебро | D4: ='УзлыРесы(1)'!B17 -> Валенсия | E4: ='УзлыРесы(1)'!D17 -> Золотые слитки, серебро
A5: ='УзлыРесы(1)'!B38 -> Деревня Тариффа | B5: ='УзлыРесы(1)'!D38 -> Кувшин заклинателя Тариф | D5: ='УзлыРесы(1)'!B41 -> Шакату | E5: ='УзлыРесы(1)'!D41 -> Золотые слитки, серебро
A6: ='УзлыРесы(1)'!B39 -> Деревня Абун | B6: ='УзлыРесы(1)'!D39 -> Деревянная кукла Абун | D6: ='УзлыРесы(1)'!B42 -> Восточный базар | E6: ='УзлыРесы(1)'!D42 -> Золотые слитки, серебро
A7: ='УзлыРесы(1)'!B40 -> Паучья Деревня | B7: ='УзлыРесы(1)'!D40 -> Сундук с тканями | D7: ='УзлыРесы(1)'!B44 -> Деревня Арехаза | E7: ='УзлыРесы(1)'!D44 -> Ящик с отличными кокосами
A8: ='УзлыРесы(1)'!L74 -> Остров Фильвара | B8: ='УзлыРесы(1)'!N74 -> Сушеный хек/камбала/голубой хирург/барбус ! Круглобрюшек/окунь/голубой хирург/щука | D8: ='УзлыРесы(1)'!Q72 -> Анакреон | E8: ='УзлыРесы(1)'!S72 -> Инжир
A9: ='УзлыРесы(1)'!L82 -> Остров Бэйрува | B9: ='УзлыРесы(1)'!N82 -> Сушеная камбала/дитрем/хек/голубой хирург | D9: ='УзлыРесы(1)'!G55 -> Лагерь клана Басим | E9: ='УзлыРесы(1)'!I55 -> Железная руда, пыль тьмы, грубый черный хрусталь
A10: ='УзлыРесы(1)'!Q34 -> Лавовая пещера (скрытый) | B10: ='УзлыРесы(1)'!S34 -> Цинковая руда, пыль веков, платиновая руда. Уголь, пыль разрушения, грубый рубин | D10: ='УзлыРесы(1)'!G62 -> Храм полумесяца | E10: ='УзлыРесы(1)'!I62 -> Финики. Титан, пыль огня, грубый фиолетовый хрусталь
A11: ='УзлыРесы(1)'!G4 -> Пастбище каменной пустоши | B11: ='УзлыРесы(1)'!I4 -> Соломенный портфель Аслана | D11: ='УзлыРесы(1)'!G63 -> Долина Титума | E11: ='УзлыРесы(1)'!I63 -> Фисташки. Теф. Древесина, сок, доска пальмы
A12: ='УзлыРесы(1)'!Q38 -> Ферма Сури | B12: ='УзлыРесы(1)'!S38 -> Батат, хороший батат, отборный батат. Ящик с отборным бататом | D12: ='УзлыРесы(1)'!G65 -> Серный рудник | E12: ='УзлыРесы(1)'!I65 -> Сера, пыль разрушения, грубый алмаз, синяя сера
A13: ='УзлыРесы(1)'!Q39 -> Ферма Касулы | B13: ='УзлыРесы(1)'!S39 -> Хлопок, хлопковое полотно. Корица. Сундучок Касулы | D13: ='УзлыРесы(1)'!Q49 -> Змеиная пустошь | E13: ='УзлыРесы(1)'!S49 -> Древесина/доска/сок бузины. Фисташки
A14: ='УзлыРесы(1)'!Q43 -> Деревня удильщиков | B14: ='УзлыРесы(1)'!S43 -> Набор рыболова | D14: ='УзлыРесы(1)'!Q50 -> Ущелье скорби | E14: ='УзлыРесы(1)'!S50 -> Древесина/доска/сок бузины.
A15: ='УзлыРесы(1)'!G45 -> Закрытая шахта / Заброшенный железный рудник (скрытый) | B15: ='УзлыРесы(1)'!I45 -> Цинковая, платиновая руда, пыль веков. Железная руда, пыль тьмы, грубый черный хрусталь | D15: ='УзлыРесы(1)'!Q51 -> Владения Куниды | E15: ='УзлыРесы(1)'!S51 -> Грязь, очищенная вода
A16: ='УзлыРесы(1)'!G46 -> Пристанище безумца | B16: ='УзлыРесы(1)'!I46 -> Черноголовка, пучок черноголовки | D16: ='УзлыРесы(1)'!Q52 -> Водопад Рейны | E16: ='УзлыРесы(1)'!S52 -> Грязь, очищенная вода
A17: ='УзлыРесы(1)'!G49 -> Храм Эллик | B17: ='УзлыРесы(1)'!I49 -> Древесина, сок пихты. Сучок кровавого дерева. Волнушка, большая волнушка | D17: ='УзлыРесы(1)'!Q53 -> Ущелье Фуркан | E17: ='УзлыРесы(1)'!S53 -> Медная руда, пыль огня, грубый опал
A18: ='УзлыРесы(1)'!L75 -> Остров Деплинхард | B18: ='УзлыРесы(1)'!N75 -> Сушеная камбала/хек/голубой хирург/язь ! Круглобрюшек/дитрем/голубой хирург/окунь | D18: ='УзлыРесы(1)'!Q55 -> Иллирия | E18: ='УзлыРесы(1)'!S55 -> Медная руда, пыль огня, грубый опал. Теф
A19: ='УзлыРесы(1)'!L83 -> Остров Тарамура | B19: ='УзлыРесы(1)'!N83 -> Сушеная камбала/хек/голубой хирург ! Круглобрюшек/дитрем/хек/окунь | D19: ='УзлыРесы(1)'!Q58 -> Могила мучеников | E19: ='УзлыРесы(1)'!S58 -> Кора/сок/шип кактуса. Железная руда, пыль тьмы, грубый черный хрусталь.
A20: ='УзлыРесы(1)'!Q26 -> Каменная пустошь | B20: ='УзлыРесы(1)'!S26 -> Древесина / сок акации. Сучок кровавого дерева | D20: ='УзлыРесы(1)'!Q60 -> Ущелье Пэмбу | E20: ='УзлыРесы(1)'!S60 -> Фрике
A21: ='УзлыРесы(1)'!Q27 -> Северное плато Медии | B21: ='УзлыРесы(1)'!S27 -> Древесина / сок пихты, кора старого дерева. Древесина / сок клёна, кора старого дерева. | D21: ='УзлыРесы(1)'!Q61 -> Ущелье Айрис | E21: ='УзлыРесы(1)'!S61 -> Древесина/доска/сок бузины. Мускатный орех.
A22: ='УзлыРесы(1)'!Q29 -> Храм Камасильва | B22: ='УзлыРесы(1)'!S29 -> Лен, льняная нить. Опёнок, большой опенок. | D22: ='УзлыРесы(1)'!Q62 -> Каньон Марша | E22: ='УзлыРесы(1)'!S62 -> Ванадий, пыль разрушения, грубый черный хрусталь. Бадьян
A23: ='УзлыРесы(1)'!Q36 -> Место раскопок (Скрытый) | B23: ='УзлыРесы(1)'!S36 -> Потускневший фрагмент голема, осколок украшения клана Тугу, Порошок земли / хаоса | D23: ='УзлыРесы(1)'!Q68 -> Святилище паломников Скромность (скрытый) | E23: ='УзлыРесы(1)'!S68 -> Печать стрелка древних, порошое памяти.
A24: ='УзлыРесы(1)'!Q37 -> Ферма Эхто | B24: ='УзлыРесы(1)'!S37 -> Хлопок, хлопокове полотно. Алоэ. Мешочек с семенами Моны. | D24: ='УзлыРесы(1)'!Q73 -> Гора полумесяца | E24: ='УзлыРесы(1)'!S73 -> Железная руда, пыль тьмы, грубый черный хрусталь.
A25: ='УзлыРесы(1)'!Q40 -> Древний разлом | B25: ='УзлыРесы(1)'!S40 -> Цинковая руда, пыль веков, грубый красный хрусталь. Черноголовка, пучок черноголовки. | D25: ='УзлыРесы(1)'!Q75 -> Фермарский базар | E25: ='УзлыРесы(1)'!S75 -> Мускатный орех. Теф. Картина верблюда
A26: ='УзлыРесы(1)'!Q41 -> Побережье Медии | B26: ='УзлыРесы(1)'!S41 -> Медная руда, пыль огня , грубый опал | D26: ='УзлыРесы(1)'!Q76 -> Поля Шакату | E26: ='УзлыРесы(1)'!S76 -> Бадьян. Инжир. Янтарь с инклюзом
B27: 23 | D27: ='УзлыРесы(1)'!Q77 -> Поля Тасмана | E27: ='УзлыРесы(1)'!S77 -> Теф. Ящик с зерном.
D28: ='УзлыРесы(1)'!Q78 -> Ферма Эрдаль | E28: ='УзлыРесы(1)'!S78 -> Фисташки. Финики. Коробка сладкого мармелада. Кокон, шелковая нить.
D29: ='УзлыРесы(1)'!Q79 -> Платация Валенсии | E29: ='УзлыРесы(1)'!S79 -> Фрике. Фисташки. Финики. Ящик с сушеными финиками.
D30: ='УзлыРесы(1)'!Q80 -> Ферма Фохаллама | E30: ='УзлыРесы(1)'!S80 -> Теф. Ящик с пустынными злаками
D31: ='УзлыРесы(1)'!Q86 -> Остров Мадина | E31: ='УзлыРесы(1)'!S86 -> БАРТЕР
D32: ='УзлыРесы(1)'!Q95 -> Пальмовый лес Арехаза | E32: ='УзлыРесы(1)'!S95 -> Древесина/доска пальмы. Кокос.
D33: ='УзлыРесы(1)'!Q98 -> Северные дюны | E33: ='УзлыРесы(1)'!S98 -> Кора/сок/шип кактуса.
D34: ='УзлыРесы(1)'!Q99 -> Вулкан Габи | E34: ='УзлыРесы(1)'!S99 -> Ванадий,пыль разрушения,грубый синий хрусталь. Титан,пыль огня,грубый фиолетовый хрусталь
D35: ='УзлыРесы(1)'!Q100 -> Кратер Габи | E35: ='УзлыРесы(1)'!S100 -> Титан,пыль огня,грубый фиолетовый хрусталь
D36: ='УзлыРесы(1)'!Q101 -> Прибрежные скалы Габи | E36: ='УзлыРесы(1)'!S101 -> Ванадий,пыль тьмы,грубый опал. Календула, пучок календулы.
D37: ='УзлыРесы(1)'!Q103 -> Утес Иверо | E37: ='УзлыРесы(1)'!S103 -> Боровик,хороший боровик, отборный боровик
E38: 34

Sheet Кама-Дриган-Одилита-Горы
A1: Автор гайда (и этой таблички) по добыче ресурсов на узлах и баракам для рабов в БДО - Стаффи
A3: Узлы Камасильвии (11 шт.) | B3: Добываемый ресурс | D3: Узлы Одиллиты (8 шт.) | E3: Добываемый ресурс
A4: ='УзлыРесы(1)'!B18 -> Грана | B4: ='УзлыРесы(1)'!D18 -> Древесина/доска пальмы. Кокос | D4: ='УзлыРесы(1)'!V61 -> Колючий лес | E4: ='УзлыРесы(1)'!X61 -> Терновая древесина / сок
A5: ='УзлыРесы(1)'!V36 -> Горная деревня | B5: ='УзлыРесы(1)'!X36 -> Клубника, хорошая клубника | D5: ='УзлыРесы(1)'!V62 -> Склеп забытых мыслей | E5: ='УзлыРесы(1)'!X62 -> Сгусток чистых чар. Порошок битвы
A6: ='УзлыРесы(1)'!V40 -> Озеро Флондор | B6: ='УзлыРесы(1)'!X40 -> Зеленая руда, пыль притяжения | D6: ='УзлыРесы(1)'!V63 -> Наксион | E6: ='УзлыРесы(1)'!X63 -> Курица,яйцо
A7: ='УзлыРесы(1)'!G71 -> Плетеный лес | B7: ='УзлыРесы(1)'!I71 -> Кольцевидная древесина, сок, доска | D7: ='УзлыРесы(1)'!V66 -> Порт Звездной полночи | E7: ='УзлыРесы(1)'!X66 -> Сушеный остронос/колючая камбала/запрора/красный хейлин
A8: ='УзлыРесы(1)'!G72 -> Лес альв | B8: ='УзлыРесы(1)'!I72 -> Костяное ожерелье. Порошок леса. Бетелома | D8: ='УзлыРесы(1)'!V71 -> Долина Оллуна | E8: ='УзлыРесы(1)'!X71 -> Никелиевая руда, мельхиор. Пыль тьмы
A9: ='УзлыРесы(1)'!V32 -> Пруд Антаци | B9: ='УзлыРесы(1)'!X32 -> Сияние Антаци | D9: ='УзлыРесы(1)'!V77 -> Плантация Деллимор | E9: ='УзлыРесы(1)'!X77 -> Виноград. Картофель.
A10: ='УзлыРесы(1)'!V34 -> Тенистый лес | B10: ='УзлыРесы(1)'!X34 -> Мшистая древесина/доска. Сок мшистого дерева | D10: ='УзлыРесы(1)'!V78 -> Горы разделения | E10: ='УзлыРесы(1)'!X78 -> Порошок вреда, сгусток чистых чар
A11: ='УзлыРесы(1)'!V35 -> Одинокий лес | B11: ='УзлыРесы(1)'!X35 -> Зеленая руда, пыль веков | D11: ='УзлыРесы(1)'!V79 -> Тропа лезвий | E11: ='УзлыРесы(1)'!X79 -> Терновая древесина/сок
A12: ='УзлыРесы(1)'!V41 -> Лес Полли | B12: ='УзлыРесы(1)'!X41 -> Синяк, Розовый гомпус | E12: 8
A13: ='УзлыРесы(1)'!V44 -> Лесная хижина Реони | B13: ='УзлыРесы(1)'!X44 -> Белый гриб, цветущий гриб
A14: ='УзлыРесы(1)'!V45 -> Лесная хижина Винни | B14: ='УзлыРесы(1)'!X45 -> Вулканический гриб, зеленая тулостома
B15: 11
A19: Узлы Дригана (11 шт.) | B19: Добываемый ресурс | D19: Узлы Гор вечной зимы (10 шт.) | E19: Добываемый ресурс
A20: ='УзлыРесы(1)'!B19 -> Двенкрун | B20: ='УзлыРесы(1)'!D19 -> Золотые слитки, серебро | D20: ='УзлыРесы(1)'!V83 -> Гнездо Ноуля Ветра | E20: ='УзлыРесы(1)'!X83 -> Древесина / сок снежного кедра
A21: ='УзлыРесы(1)'!G5 -> Лесопилка Дормана | B21: ='УзлыРесы(1)'!I5 -> Древесина, доска, сок кипариса. Древесина, доска, сок плосковеточника. | D21: ='УзлыРесы(1)'!V85 -> Сад Маслан с Юдзу | E21: ='УзлыРесы(1)'!X85 -> Юдзу
A22: ='УзлыРесы(1)'!V58 -> Лесопилка Химута | B22: ='УзлыРесы(1)'!X58 -> Древесина, доска, сок сосны. Древесина, доска, сок ольхи. | D22: ='УзлыРесы(1)'!V87 -> Горы вечной зимы | E22: ='УзлыРесы(1)'!X87 -> Прозрачный лёд, Кусок прозрачного льда
A23: ='УзлыРесы(1)'!G75 -> Скалы Акумуса | B23: ='УзлыРесы(1)'!I75 -> Железная руда, зеленая руда, грубый лазурит | D23: ='УзлыРесы(1)'!V89 -> Лес Нефритовых звезд | E23: ='УзлыРесы(1)'!X89 -> Древесина / сок снежного кедра. Грубый нефрит
A24: ='УзлыРесы(1)'!V49 -> Поля Двенкруна | B24: ='УзлыРесы(1)'!X49 -> Ячмень. Кукуруза | D24: ='УзлыРесы(1)'!V90 -> Сторожевой пост на гором перевале | E24: ='УзлыРесы(1)'!X90 -> Древесина Ольхи, ветвь монарха
A25: ='УзлыРесы(1)'!V50 -> Каньон Карков | B25: ='УзлыРесы(1)'!X50 -> Зеленая руда. Мельхиор. Цинковая руда. | D25: ='УзлыРесы(1)'!V91 -> Лес Тори | E25: ='УзлыРесы(1)'!X91 -> Орляк
A26: ='УзлыРесы(1)'!V51 -> Могила Шерехана | B26: ='УзлыРесы(1)'!X51 -> Кусок высохшего камня. Порошок памяти. | D26: ='УзлыРесы(1)'!V92 -> Рудник Шерехана | E26: ='УзлыРесы(1)'!X92 -> Грубый обсидиан. Порошок починки, кварц
A27: ='УзлыРесы(1)'!V56 -> Ручей желаний | B27: ='УзлыРесы(1)'!X56 -> Кусок магического камня. Порошок изначальности | D27: ='УзлыРесы(1)'!V95 -> Холм Звиер | E27: ='УзлыРесы(1)'!X95 -> Порошок смерти. Кварц. Мёд
A28: ='УзлыРесы(1)'!V57 -> Горы Гервиша | B28: ='УзлыРесы(1)'!X57 -> Орляк. Календула | D28: ='УзлыРесы(1)'!V96 -> Лагерь Балакс | E28: ='УзлыРесы(1)'!X96 -> Раскаленный черный минерал
A29: ='УзлыРесы(1)'!V59 -> Руины Тширы | B29: ='УзлыРесы(1)'!X59 -> Орляк. Клевер | D29: ='УзлыРесы(1)'!V98 -> Путь последнего паломничества | E29: ='УзлыРесы(1)'!X98 -> Лисички, мешима. Пятнистый рыжик, Бамбуковый гриб
A30: ='УзлыРесы(1)'!V60 -> Ферма Марака | B30: ='УзлыРесы(1)'!X60 -> Кукуруза. Ячмень. | E30: 10
B31: 11

Sheet Бараки
A1: Количество рабочих в городе = количество бараков +1 | W1: Автор гайда (и этой таблички) по добыче ресурсов на узлах и баракам для рабов в БДО - Стаффи
A3: Баленос | B3: Дом | C3: Следование | D3: Бараки | E3: Очки | F3: ∑мест | G3: ∑очк | H3: Цена1 бар. | I3: Примечание | K3: Валенсия | L3: Дом | M3: Следование | N3: Бараки | O3: Очки | P3: ∑мест | Q3: ∑очк | R3: Цена1 бар. | S3: Примечание | U3: Кальфеон Округ | V3: Дом | W3: Следование | X3: Бараки | Y3: Очки | Z3: ∑мест | AA3: ∑очк | AB3: Цена1 бар. | AC3: Примечание | AE3: КАЛЬФЕОН | AF3: Дом | AG3: Следование | AH3: Ячейки | AI3: Очки | AJ3: ∑яч. | AK3: ∑очк | AL3: Цена1яч. | AM3: Примечание | AO3: КАМАСИЛЬВИЯ | AP3: Дом | AQ3: Следование | AR3: Ячейки | AS3: Очки | AT3: ∑яч. | AU3: ∑очк | AV3: Цена1яч. | AW3: Примечание
A4: Оливия | B4: 2-1 | C4: первый | D4: 0 | E4: 1 | F4: =D4 -> 0 | G4: =E4 -> 1 | H4: =G4 -> 1 | I4: --- | K4: Валенсия | L4: 1-1-1 | M4: первый | N4: 1 | O4: 1 | P4: =N4 -> 1 | Q4: =O4 -> 1 | R4: =Q4/P4 -> 1 | S4: бараки 1 | U4: Кеплан | V4: 1-1 | W4: первый | X4: 0 | Y4: 1 | Z4: =X4 -> 0 | AA4: =Y4 -> 1 | AB4: =AA4 -> 1 | AC4: --- | AE4: Кальфеон | AF4: Северные ворота 4-1 | AG4: первый | AH4: 1 | AI4: 1 | AJ4: =AH4 -> 1 | AK4: =AI4 -> 1 | AL4: =AK4/AJ4 -> 1 | AM4: бараки 1 | AO4: Грана | AP4: 7 | AQ4: первый | AR4: 2 | AS4: 5 | AT4: 2 | AU4: 3 | AV4: =AU4/AT4 -> 1.5 | AW4: Бараки 2
A5: Оливия | B5: 2-1а | C5: второй | D5: 2 | E5: 3 | F5: =D4+D5 -> 2 | G5: =E4+E5 -> 4 | H5: =G5/F5 -> 2 | I5: бараки 2 | K5: Валенсия | L5: 1-1-2 | M5: второй | N5: 2 | O5: 2 | P5: =N4+N5 -> 3 | Q5: =O4+O5 -> 3 | R5: =Q5/P5 -> 1 | S5: бараки 2 | U5: Кеплан | V5: 1-2-1 | W5: второй | X5: 1 | Y5: 2 | Z5: =X4+X5 -> 1 | AA5: =Y4+Y5 -> 3 | AB5: =AA5/Z5 -> 3 | AC5: барак 1 | AE5: Кальфеон | AF5: Северные ворота 4-2 | AG5: второй | AH5: 1 | AI5: 1 | AJ5: =AH4+AH5 -> 2 | AK5: =AI4+AI5 -> 2 | AL5: =AK5/AJ5 -> 1 | AM5: бараки 1 | AO5: Грана | AP5: 10 | AQ5: первый | AR5: 3 | AS5: 8 | AT5: =AR4+AR5 -> 5 | AU5: =AS4+AS5 -> 13 | AV5: =AU5/AT5 -> 2.6 | AW5: Бараки 3
A6: Оливия | B6: 2-2 | C6: второй | D6: 1 | E6: 1 | F6: =D4+D6 -> 1 | G6: =E4+E6 -> 2 | H6: =G6/F6 -> 2 | I6: бараки 1 | K6: Валенсия | L6: 1-2 | M6: второй | N6: 3 | O6: 3 | P6: =N4+N6 -> 4 | Q6: =O4+O6 -> 4 | R6: =Q6/P6 -> 1 | S6: бараки 3 | U6: Кеплан | V6: 1-3-1 | W6: третий | X6: 1 | Y6: 1 | Z6: =X4+X5+X6 -> 2 | AA6: =Y4+Y5+Y6 -> 4 | AB6: =AA6/Z6 -> 2 | AC6: барак 1 | AE6: Кальфеон | AF6: Северные ворота 3 | AG6: второй | AH6: 2 | AI6: 2 | AJ6: =AH4+AH6 -> 3 | AK6: =AI4+AI6 -> 3 | AL6: =AK6/AJ6 -> 1 | AM6: бараки 2 | AO6: Грана | AP6: 16 | AQ6: первый | AR6: 2 | AS6: 5 | AT6: =AR4+AR5+AR6 -> 7 | AU6: =AS4+AS5+AS6 -> 18 | AV6: =AU6/AT6 -> 2.5714286 | AW6: Бараки 2
A7: Оливия | B7: 2-3 | C7: третий | D7: 2 | E7: 1 | F7: =D4+D6+D7 -> 3 | G7: =E4+E6+E7 -> 3 | H7: =G7/F7 -> 1 | I7: бараки 2 | K7: Валенсия | L7: 1-3-1 | M7: третий | N7: 2 | O7: 2 | P7: =N4+N6+N7 -> 6 | Q7: =O4+O6+O7 -> 6 | R7: =Q7/P7 -> 1 | S7: бараки 2 | U7: Кеплан | V7: 1-4-1 | W7: четвертый | X7: 1 | Y7: 1 | Z7: =X4+X5+X6+X7 -> 3 | AA7: =Y4+Y5+Y6+Y7 -> 5 | AB7: =AA7/Z7 -> 1.6666667 | AC7: барак 1 | AE7: Кальфеон | AF7: Северные ворота 2 | AG7: третий | AH7: 2 | AI7: 3 | AJ7: =AH4+AH6+AH7 -> 5 | AK7: =AI4+AI6+AI7 -> 6 | AL7: =AK7/AJ7 -> 1.2 | AM7: бараки 2 | AO7: Итого бараков: | AR7: =SUM(AR4:AR6) -> 7
A8: Оливия | B8: 6-1 | C8: первый | D8: 1 | E8: 1 | F8: =D8 -> 1 | G8: =E8 -> 1 | H8: =G8/F8 -> 1 | I8: бараки 1 | K8: Валенсия | L8: 2-1 | M8: первый | N8: 1 | O8: 1 | P8: =N8 -> 1 | Q8: =O8 -> 1 | R8: =Q8/P8 -> 1 | S8: бараки 1 | U8: Кеплан | V8: 2-1-2 | W8: первый | X8: 0 | Y8: 1 | Z8: =X8 -> 0 | AA8: 1 | AB8: =AA8 -> 1 | AC8: --- | AE8: Кальфеон | AF8: Северные ворота 1 | AG8: четвертый | AH8: 3 | AI8: 3 | AJ8: =AH4+AH6+AH7+AH8 -> 8 | AK8: =AI4+AI6+AI7+AI8 -> 9 | AL8: =AK8/AJ8 -> 1.125 | AM8: бараки 3
A9: Оливия | B9: 6-2 | C9: второй | D9: 2 | E9: 2 | F9: =D8+D9 -> 3 | G9: =E8+E9 -> 3 | H9: =G9/F9 -> 1 | I9: бараки 2 | K9: Валенсия | L9: 2-2-1 | M9: второй | N9: 1 | O9: 1 | P9: =N8+N9 -> 2 | Q9: =O8+O9 -> 2 | R9: =Q9/P9 -> 1 | S9: бараки 1 | U9: Кеплан | V9: 2-2-1 | W9: второй | X9: 1 | Y9: 2 | Z9: =X8+X9 -> 1 | AA9: =Y8+Y9 -> 3 | AB9: =AA9/Z9 -> 3 | AC9: барак 1 | AE9: Кальфеон | AF9: Южные ворота 1 | AG9: первый | AH9: 2 | AI9: 2 | AJ9: =AH9 -> 2 | AK9: =AI9 -> 2 | AL9: =AK9/AJ9 -> 1 | AM9: бараки 2 | AO9: ДРИГАН | AP9: Дом | AQ9: Следование | AR9: Ячейки | AS9: Очки | AT9: ∑яч. | AU9: ∑очк | AV9: Цена1яч. | AW9: Примечание
A10: Оливия | B10: 6-3 | C10: третий | D10: 3 | E10: 2 | F10: =D8+D9+D10 -> 6 | G10: =E8+E9+E10 -> 5 | H10: =G10/F10 -> 0.83333333 | I10: бараки 3 | K10: Валенсия | L10: 2-2-2 | M10: третий | N10: 2 | O10: 2 | P10: =N8+N9+N10 -> 4 | Q10: =O8+O9+O10 -> 4 | R10: =Q10/P10 -> 1 | S10: бараки 2 | U10: Кеплан | V10: 2-2-2 | W10: третий | X10: 2 | Y10: 5 | Z10: =X8+X9+X10 -> 3 | AA10: =Y8+Y9+Y10 -> 8 | AB10: =AA10/Z10 -> 2.6666667 | AC10: барак 2 | AE10: Кальфеон | AF10: Южные ворота 2-1 | AG10: второй | AH10: 2 | AI10: 1 | AJ10: =AH9+AH10 -> 4 | AK10: =AI9+AI10 -> 3 | AL10: =AK10/AJ10 -> 0.75 | AM10: бараки 2 | AO10: Двенкрун | AP10: 3 | AQ10: первый | AR10: 2 | AS10: 8 | AT10: =AR10 -> 2 | AU10: =AS10 -> 8 | AV10: =AU10/AT10 -> 4 | AW10: Бараки 2
A11: Оливия | B11: 7-1 | C11: первый | D11: 1 | E11: 1 | F11: =D11 -> 1 | G11: =E11 -> 1 | H11: =G11/F11 -> 1 | I11: бараки 1 | K11: Валенсия | L11: 3-1 | M11: первый | N11: 1 | O11: 1 | P11: =N11 -> 1 | Q11: =O11 -> 1 | R11: =Q11/P11 -> 1 | S11: бараки 1 | U11: Кеплан | V11: 3-1 | W11: первый | X11: 1 | Y11: 2 | Z11: 3 | AA11: 1 | AB11: =AA11/Z11 -> 0.33333333 | AC11: барак 1 | AE11: Кальфеон | AF11: Южные ворота 2-2 | AG11: третий | AH11: 3 | AI11: 2 | AJ11: =AH9+AH10+AH11 -> 7 | AK11: =AI9+AI10+AI11 -> 5 | AL11: =AK11/AJ11 -> 0.71428571 | AM11: бараки 3 | AO11: Двенкрун | AP11: 6 | AQ11: первый | AR11: 2 | AS11: 8 | AT11: =AR11 -> 2 | AU11: =AS11 -> 8 | AV11: =AU11/AT11 -> 4 | AW11: Бараки 2
A12: Ферма Вейла | B12: 1 | C12: первый | D12: 2 | E12: 2 | F12: =D12 -> 2 | G12: =E12 -> 2 | H12: =G12/F12 -> 1 | I12: бараки 2 | K12: Валенсия | L12: 3-2-1 | M12: второй | N12: 1 | O12: 1 | P12: =N11+N12 -> 2 | Q12: =O11+O12 -> 2 | R12: =Q12/P12 -> 1 | S12: бараки 1 | U12: Кеплан | V12: 3-1 клад. | W12: второй | X12: 2 | Y12: 4 | Z12: =X11+X12 -> 3 | AA12: =Y11+Y12 -> 6 | AB12: =AA12/Z12 -> 2 | AC12: барак 2 | AE12: Кальфеон | AF12: Южные ворота 3 | AG12: первый | AH12: 0 | AI12: 1 | AJ12: =AH12 -> 0 | AK12: =AI12 -> 1 | AL12: =AK12 -> 1 | AM12: --- | AO12: Двенкрун | AP12: 8 | AQ12: первый | AR12: 2 | AS12: 8 | AT12: =AR12 -> 2 | AU12: =AS12 -> 8 | AV12: =AU12/AT12 -> 4 | AW12: Бараки 2
A13: Итого бараков: | D13: =SUM(D4:D12) -> 14 | K13: Валенсия | L13: 4-1-1 | M13: первый | N13: 1 | O13: 1 | P13: =N13 -> 1 | Q13: =O13 -> 1 | R13: =Q13/P13 -> 1 | S13: бараки 1 | U13: Ферма Джанни | V13: 1 | W13: первый | X13: 1 | Y13: 3 | Z13: =X13 -> 1 | AA13: =Y13 -> 3 | AB13: =AA13/Z13 -> 3 | AC13: барак 1 | AE13: Кальфеон | AF13: Южные ворота 4-1 | AG13: второй | AH13: 2 | AI13: 2 | AJ13: =AH12+AH13 -> 2 | AK13: =AI12+AI13 -> 3 | AL13: =AK13/AJ13 -> 1.5 | AM13: бараки 2 | AO13: Двенкрун | AP13: 11-1 | AQ13: первый | AR13: 0 | AS13: 8 | AT13: =AR13 -> 0 | AU13: =AS13 -> 8 | AV13: =AU13 -> 8 | AW13: ---
K14: Валенсия | L14: 5-1-1 | M14: первый | N14: 1 | O14: 1 | P14: =N14 -> 1 | Q14: =O14 -> 1 | R14: =Q14/P14 -> 1 | S14: бараки 1 | U14: Итого бараков: | X14: =SUM(X4:X13) -> 10 | AE14: Кальфеон | AF14: Восточные ворота 1-1 | AG14: первый | AH14: 1 | AI14: 1 | AJ14: =AH14 -> 1 | AK14: =AI14 -> 1 | AL14: =AK14/AJ14 -> 1 | AM14: бараки 1 | AO14: Двенкрун | AP14: 11-2 | AQ14: второй | AR14: 1 | AS14: 8 | AT14: =AR13+AR14 -> 1 | AU14: =AS13+AS14 -> 16 | AV14: =AU14/AT14 -> 16 | AW14: Бараки 1
A15: Велия | B15: 1-1 | C15: первый | D15: 1 | E15: 1 | F15: =D15 -> 1 | G15: =E15 -> 1 | H15: =G15/F15 -> 1 | I15: бараки 1 | K15: Валенсия | L15: 6-1-1 | M15: первый | N15: 1 | O15: 1 | P15: =N15 -> 1 | Q15: =O15 -> 1 | R15: =Q15/P15 -> 1 | S15: бараки 1 | AE15: Кальфеон | AF15: Восточные ворота 1-2 | AG15: второй | AH15: 2 | AI15: 2 | AJ15: =AH14+AH15 -> 3 | AK15: =AI14+AI15 -> 3 | AL15: =AK15/AJ15 -> 1 | AM15: бараки 2 | AO15: Итого бараков: | AR15: =SUM(AT10:AT14) -> 7
A16: Велия | B16: 1-2 | C16: второй | D16: 2 | E16: 1 | F16: =D15+D16 -> 3 | G16: =E15+E16 -> 2 | H16: =G16/F16 -> 0.66666667 | I16: бараки 2 | K16: Валенсия | L16: 7-1-1 | M16: первый | N16: 1 | O16: 1 | P16: =N16 -> 1 | Q16: =O16 -> 1 | R16: =Q16/P16 -> 1 | S16: бараки 1 | U16: Эферия | V16: 1-1-1 | W16: первый | X16: 1 | Y16: 1 | Z16: =X16 -> 1 | AA16: =Y16 -> 1 | AB16: =AA16/Z16 -> 1 | AC16: бараки 1 | AE16: Кальфеон | AF16: Восточные ворота 2 | AG16: второй | AH16: 0 | AI16: 1 | AJ16: =AH14+AH15+AH16 -> 3 | AK16: =AI14+AI16 -> 2 | AL16: =AK16 -> 2 | AM16: ---
A17: Велия | B17: 1-3 | C17: третий | D17: 2 | E17: 1 | F17: =D15+D16+D17 -> 5 | G17: =E15+E16+E17 -> 3 | H17: =G17/F17 -> 0.6 | I17: бараки 2 | K17: Валенсия | L17: 8-1 | M17: первый | N17: 1 | O17: 1 | P17: =N17 -> 1 | Q17: =O17 -> 1 | R17: =Q17/P17 -> 1 | S17: бараки 1 | U17: Эферия | V17: 1-1-2 | W17: второй | X17: 1 | Y17: 2 | Z17: =X16+X17 -> 2 | AA17: =Y16+Y17 -> 3 | AB17: =AA17/Z17 -> 1.5 | AC17: бараки 1 | AE17: Кальфеон | AF17: Восточные ворота 3 | AG17: третий | AH17: 0 | AI17: 1 | AJ17: =AH14+AH15+AH16+AH17 -> 3 | AK17: =AI14+AI16+AI17 -> 3 | AL17: =AK17 -> 3 | AM17: --- | AO17: ОДИРАКСИЯ | AP17: Дом | AQ17: Следование | AR17: Ячейки | AS17: Очки | AT17: ∑яч. | AU17: ∑очк | AV17: Цена1яч. | AW17: Примечание
A18: Ферма Тоскани | B18: 1 | C18: первый | D18: 2 | E18: 3 | F18: =D18 -> 2 | G18: =E18 -> 3 | H18: =G18/F18 -> 1.5 | I18: бараки 2 | K18: Валенсия | L18: 8-2-1 | M18: второй | N18: 1 | O18: 1 | P18: =N17+N18 -> 2 | Q18: =O17+O18 -> 2 | R18: =Q18/P18 -> 1 | S18: бараки 1 | U18: Эферия | V18: 1-2-1 | W18: второй | X18: 0 | Y18: 2 | Z18: =X16+X18 -> 1 | AA18: =Y16+Y18 -> 3 | AB18: =AA18/Z18 -> 3 | AC18: --- | AE18: Кальфеон | AF18: Восточные ворота 4-1 | AG18: четвертый | AH18: 2 | AI18: 2 | AJ18: =AH14+AH16+AH17+AH18 -> 3 | AK18: =AI14+AI16+AI17+AI18 -> 5 | AL18: =AK18/AJ18 -> 1.6666667 | AM18: бараки 2 | AO18: Одиллита | AP18: 1 | AQ18: первый | AR18: 1 | AS18: 2 | AT18: =AR18 -> 1 | AU18: =AS18 -> 2 | AV18: =AU18/AT18 -> 2 | AW18: Бараки 1
A19: Итого бараков: | D19: =SUM(D15:D18) -> 7 | E19: еще +1 барак за мили | K19: Валенсия | L19: 9-1 | M19: первый | N19: 1 | O19: 1 | P19: =N19 -> 1 | Q19: =O19 -> 1 | R19: =Q19/P19 -> 1 | S19: бараки 1 | U19: Эферия | V19: 1-2-2 | W19: третий | X19: 1 | Y19: 2 | Z19: =X16+X18+X19 -> 2 | AA19: =Y16+Y18+Y19 -> 5 | AB19: =AA19/Z19 -> 2.5 | AC19: бараки 1 | AE19: Кальфеон | AF19: Восточные ворота 4-2 | AG19: пятый | AH19: 3 | AI19: 3 | AJ19: =AH14+AH16+AH17+AH18+AH19 -> 6 | AK19: =AI14+AI16+AI17+AI18+AI19 -> 8 | AL19: =AK19/AJ19 -> 1.3333333 | AM19: бараки 3 | AO19: Одиллита | AP19: 2 | AQ19: второй | AR19: 2 | AS19: 2 | AT19: =AR18+AR19 -> 3 | AU19: =AS18+AS19 -> 4 | AV19: =AU19/AT19 -> 1.3333333 | AW19: Бараки 2
K20: Валенсия | L20: 11-1 | M20: первый | N20: 1 | O20: 1 | P20: =N20 -> 1 | Q20: =O20 -> 1 | R20: =Q20/P20 -> 1 | S20: бараки 1 | U20: Эферия | V20: 1-3 | W20: третий | X20: 0 | Y20: 4 | Z20: =X16+X18+X20 -> 1 | AA20: =Y16+Y18+Y20 -> 7 | AB20: =AA20/Z20 -> 7 | AC20: --- | AE20: Кальфеон | AF20: Восточные ворота 4-3 | AG20: шестой | AH20: 3 | AI20: 3 | AJ20: =AH14+AH16+AH17+AH18+AH19+AH20 -> 9 | AK20: =AI14+AI16+AI17+AI18+AI19+AI20 -> 11 | AL20: =AK20/AJ20 -> 1.2222222 | AM20: бараки 3 | AO20: Одиллита | AP20: 3 | AQ20: третий | AR20: 2 | AS20: 3 | AT20: =AR18+AR19+AR20 -> 5 | AU20: =AS18+AS19+AS20 -> 7 | AV20: =AU20/AT20 -> 1.4 | AW20: Бараки 2
A21: Остров Илия | B21: 4-2 | C21: первый | D21: 1 | E21: 1 | F21: =D21 -> 1 | G21: =E21 -> 1 | H21: =G21/F21 -> 1 | I21: бараки 1 | K21: Валенсия | L21: 11-2-1 | M21: второй | N21: 1 | O21: 1 | P21: =N20+N21 -> 2 | Q21: =O20+O21 -> 2 | R21: =Q21/P21 -> 1 | S21: бараки 1 | U21: Эферия | V21: 1-4-1 | W21: четвертый | X21: 3 | Y21: 2 | Z21: =X16+X18+X20+X21 -> 4 | AA21: =Y16+Y18+Y20+Y21 -> 9 | AB21: =AA21/Z21 -> 2.25 | AC21: бараки 3 | AE21: Кальфеон | AF21: Восточные ворота 7 | AG21: первый | AH21: 1 | AI21: 1 | AJ21: =AH21 -> 1 | AK21: =AI21 -> 1 | AL21: =AK21/AJ21 -> 1 | AM21: бараки 1 | AO21: Одиллита | AP21: 4 | AQ21: четвертый | AR21: 3 | AS21: 4 | AT21: =AR18+AR19+AR20+AR21 -> 8 | AU21: =AS18+AS19+AS20+AS21 -> 11 | AV21: =AU21/AT21 -> 1.375 | AW21: Бараки 3
A22: Остров Илия | B22: 6-1 | C22: первый | D22: 0 | E22: 1 | F22: =D22 -> 0 | G22: =E22 -> 1 | H22: =G22 -> 1 | I22: --- | K22: Валенсия | L22: 12-1-1 | M22: первый | N22: 1 | O22: 1 | P22: =N22 -> 1 | Q22: =O22 -> 1 | R22: =Q22/P22 -> 1 | S22: бараки 1 | U22: Эферия | V22: 1-4-2 | W22: пятый | X22: 3 | Y22: 3 | Z22: =X16+X18+X20+X21+X22 -> 7 | AA22: =Y16+Y18+Y20+Y21+Y22 -> 12 | AB22: =AA22/Z22 -> 1.7142857 | AC22: бараки 3 | AE22: Кальфеон | AF22: Восточные ворота 8-1 | AG22: второй | AH22: 1 | AI22: 1 | AJ22: =AH21+AH22 -> 2 | AK22: =AI21+AI22 -> 2 | AL22: =AK22/AJ22 -> 1 | AM22: бараки 1 | AO22: Одиллита | AP22: 5 | AQ22: пятый | AR22: 3 | AS22: 5 | AT22: =AR18+AR19+AR20+AR21+AR22 -> 11 | AU22: =AS18+AS19+AS20+AS21+AS22 -> 16 | AV22: =AU22/AT22 -> 1.4545455 | AW22: Бараки 3
A23: Остров Илия | B23: 6-2 | C23: второй | D23: 1 | E23: 2 | F23: =D22+D23 -> 1 | G23: =E22+E23 -> 3 | H23: =G23/F23 -> 3 | I23: бараки 1 | K23: Валенсия | L23: 13-1-1 | M23: первый | N23: 1 | O23: 1 | P23: =N23 -> 1 | Q23: =O23 -> 1 | R23: =Q23/P23 -> 1 | S23: бараки 1 | U23: Эферия | V23: 2-1к1 | W23: первый | X23: 1 | Y23: 1 | Z23: =X23 -> 1 | AA23: =Y23 -> 1 | AB23: =AA23/Z23 -> 1 | AC23: бараки 1 | AE23: Кальфеон | AF23: Трущебы 1-3-1 | AG23: первый | AH23: 1 | AI23: 1 | AJ23: =AH23 -> 1 | AK23: =AI23 -> 1 | AL23: =AK23/AJ23 -> 1 | AM23: бараки 1 | AO23: Итого бараков: | AR23: =SUM(AR18:AR22) -> 11
A24: Итого бараков: | D24: =SUM(D21:D23) -> 2 | K24: Валенсия | L24: 14-1-1 | M24: первый | N24: 1 | O24: 1 | P24: =N24 -> 1 | Q24: =O24 -> 1 | R24: =Q24/P24 -> 1 | S24: бараки 1 | U24: Эферия | V24: 2-1к2 | W24: второй | X24: 1 | Y24: 1 | Z24: =X23+X24 -> 2 | AA24: =Y23+Y24 -> 2 | AB24: =AA24/Z24 -> 1 | AC24: бараки 1 | AE24: Кальфеон | AF24: Трущебы 1-3-2 | AG24: второй | AH24: 1 | AI24: 1 | AJ24: =AH23+AH24 -> 2 | AK24: =AI23+AI24 -> 2 | AL24: =AK24/AJ24 -> 1 | AM24: бараки 1
K25: Валенсия | L25: 15-1-1 | M25: первый | N25: 1 | O25: 1 | P25: =N25 -> 1 | Q25: =O25 -> 1 | R25: =Q25/P25 -> 1 | S25: бараки 1 | U25: Эферия | V25: 2-1-1 | W25: второй | X25: 0 | Y25: 2 | Z25: =X23+X25 -> 1 | AA25: =Y23+Y25 -> 3 | AB25: =AA25/Z25 -> 3 | AC25: --- | AE25: Кальфеон | AF25: Трущебы 1-4-1 | AG25: второй | AH25: 1 | AI25: 2 | AJ25: =AH23+AH25 -> 2 | AK25: =AI23+AI25 -> 3 | AL25: =AK25/AJ25 -> 1.5 | AM25: бараки 1 | AO25: ГорыВечнойЗимы | AP25: Дом | AQ25: Следование | AR25: Ячейки | AS25: Очки | AT25: ∑яч. | AU25: ∑очк | AV25: Цена1яч. | AW25: Примечание1
A26: Серендия | B26: Дом | C26: Следование | D26: Бараки | E26: Очки | F26: ∑мест | G26: ∑очк | H26: Цена1яч. | I26: Примечание | K26: Валенсия | L26: 15-1-2 | M26: второй | N26: 2 | O26: 2 | P26: =N25+N26 -> 3 | Q26: =O25+O26 -> 3 | R26: =Q26/P26 -> 1 | S26: бараки 2 | U26: Эферия | V26: 2-2-1 | W26: третий | X26: 0 | Y26: 1 | Z26: =X23+X25+X26 -> 1 | AA26: =Y23+Y25+Y26 -> 4 | AB26: =AA26/Z26 -> 4 | AC26: --- | AE26: Кальфеон | AF26: Трущебы 2-1 | AG26: первый | AH26: 0 | AI26: 1 | AJ26: =AH26 -> 0 | AK26: =AI26 -> 1 | AL26: =AK26 -> 1 | AM26: --- | AO26: Деревня Эйл | AP26: 1 | AQ26: первый | AR26: 0 | AS26: 2 | AT26: =AR26 -> 0 | AU26: =AS26 -> 2 | AV26: =AU26 -> 2
A27: Хидель | B27: 1-1 | C27: первый | D27: 0 | E27: 1 | F27: =D27 -> 0 | G27: =E27 -> 1 | H27: =G27 -> 1 | I27: --- | K27: Валенсия | L27: 16-1 | M27: первый | N27: 1 | O27: 1 | P27: =N27 -> 1 | Q27: =O27 -> 1 | R27: =Q27/P27 -> 1 | S27: бараки 1 | U27: Эферия | V27: 2-3-1 | W27: четвертый | X27: 0 | Y27: 2 | Z27: =X23+X25+X26+X27 -> 1 | AA27: =Y23+Y25+Y26+Y27 -> 6 | AB27: =AA27/Z27 -> 6 | AC27: --- | AE27: Кальфеон | AF27: Трущебы 2-2-1 | AG27: второй | AH27: 1 | AI27: 3 | AJ27: =AH26+AH27 -> 1 | AK27: =AI26+AI27 -> 4 | AL27: =AK27/AJ27 -> 4 | AM27: бараки 1 | AO27: Деревня Эйл | AP27: 2 | AQ27: второй | AR27: 1 | AS27: 2 | AT27: =AR26+AR27 -> 1 | AU27: =AS26+AS27 -> 4 | AV27: =AU27/AT27 -> 4 | AW27: Бараки 1
A28: Хидель | B28: 1-2 | C28: второй | D28: 1 | E28: 1 | F28: =D27+D28 -> 1 | G28: =E27+E28 -> 2 | H28: =G28/F28 -> 2 | I28: барак 1 | K28: Валенсия | L28: 17-1 | M28: первый | N28: 0 | O28: 1 | P28: =N28 -> 0 | Q28: =O28 -> 1 | R28: =Q28 -> 1 | S28: --- | U28: Эферия | V28: 2-3-2 | W28: пятый | X28: 2 | Y28: 1 | Z28: =X23+X25+X26+X27+X28 -> 3 | AA28: =Y23+Y25+Y26+Y27+Y28 -> 7 | AB28: =AA28/Z28 -> 2.3333333 | AC28: бараки 2 | AE28: Кальфеон | AF28: Трущебы 2-2-2 | AG28: третий | AH28: 2 | AI28: 1 | AJ28: =AH26+AH27+AH28 -> 3 | AK28: =AI26+AI27+AI28 -> 5 | AL28: =AK28/AJ28 -> 1.6666667 | AM28: бараки 2 | AO28: Деревня Эйл | AP28: 3 | AQ28: третий | AR28: 0 | AS28: 3 | AT28: =AR26+AR27+AR28 -> 1 | AU28: =AS26+AS27+AS28 -> 7 | AV28: =AU28/AT28 -> 7
A29: Хидель | B29: 1-5 | C29: третий | D29: 2 | E29: 4 | F29: =D27+D28+D29 -> 3 | G29: =E27+E28+E29 -> 6 | H29: =G29/F29 -> 2 | I29: барак 2 | K29: Валенсия | L29: 17-2 | M29: второй | N29: 1 | O29: 2 | P29: =N28+N29 -> 1 | Q29: =O28+O29 -> 3 | R29: =Q29/P29 -> 3 | S29: бараки 1 | U29: Эферия | V29: 2-4-1 | W29: пятый | X29: 0 | Y29: 1 | Z29: =X23+X25+X26+X27+X29 -> 1 | AA29: =Y23+Y25+Y26+Y27+Y29 -> 7 | AB29: =AA29/Z29 -> 7 | AC29: --- | AE29: Кальфеон | AF29: Трущебы 2-3-2 | AG29: третий | AH29: 1 | AI29: 1 | AJ29: =AH26+AH27+AH29 -> 2 | AK29: =AI26+AI27+AI29 -> 5 | AL29: =AK29/AJ29 -> 2.5 | AM29: бараки 1 | AO29: Деревня Эйл | AP29: 4 | AQ29: четвертый | AR29: 2 | AS29: 4 | AT29: =AR26+AR27+AR28+AR29 -> 3 | AU29: =AS26+AS27+AS28+AS29 -> 11 | AV29: =AU29/AT29 -> 3.6666667 | AW29: Бараки 2
